<mujoco model="eye">
  <compiler angle="degree" coordinate="local" inertiafromgeom="true"/>
  <option timestep="0.01" solver="Newton" iterations="1" ls_iterations="4">
      <flag eulerdamp="disable"/>
  </option>
  <custom>
    <numeric data="1000" name="constraint_limit_stiffness"/>
    <numeric data="4000" name="constraint_stiffness"/>
    <numeric data="10" name="constraint_ang_damping"/>
    <numeric data="20" name="constraint_vel_damping"/>
    <numeric data="0.5" name="joint_scale_pos"/>
    <numeric data="0.2" name="joint_scale_ang"/>
    <numeric data="0" name="ang_damping"/>
    <numeric data="1" name="spring_mass_scale"/>
    <numeric data="1" name="spring_inertia_scale"/>
    <numeric data="15" name="solver_maxls"/>
  </custom>
  <default>
    <geom contype="0" conaffinity="0" condim="3" density="5" friction="1 0.5 0.5" rgba="0.4 0.33 0.26 1"/>
    <joint armature="0.045" limited="true"/>
    <position kp="100" ctrllimited="true" ctrlrange="-1.57079632679 1.57079632679" dampratio="1" forcelimited="true" forcerange="-5 5"/>
  </default>
  <asset>
    <texture builtin="gradient" height="100" rgb1="1 1 1" rgb2="0 0 0" type="skybox" width="100"/>
    <texture builtin="flat" height="1278" mark="cross" markrgb="1 1 1" name="texgeom" random="0.01" rgb1="0.8 0.6 0.4" rgb2="0.8 0.6 0.4" type="cube" width="127"/>
    <texture builtin="checker" height="100" name="texplane" rgb1="0 0 0" rgb2="0.8 0.8 0.8" type="2d" width="100"/>
    <material name="MatPlane" reflectance="0.5" shininess="1" specular="1" texrepeat="60 60" texture="texplane"/>
    <material name="geom" texture="texgeom" texuniform="true"/>
  </asset>
  <worldbody>
    <light cutoff="100" diffuse="1 1 1" dir="-0 0 -1.3" directional="true" exponent="1" pos="0 0 1.3" specular=".1 .1 .1"/>
    <geom conaffinity="1" condim="3" material="MatPlane" name="floor" size="40 40 40" type="plane" rgba="0.5 0.5 0.5 1"/>
    <body name="torso" pos="0 0 1">
      <camera name="track" mode="trackcom" pos="0 -3 0.3" xyaxes="1 0 0 0 0 1"/>
      <geom name="torso" size="0.25" type="sphere"/>
      <site name="imu"/>
      <joint armature="0" damping="0" limited="false" margin="0.01" name="root" type="free"/>
      <replicate count="3" euler="0 0 120">
        <body name="leg">
          <geom fromto="0 0 0 0.3 0 0" name="aux" size="0.08" type="capsule"/>
          <body name="aux" pos="0.3 0 0">
            <joint axis="1 0 0" name="roll" type="hinge" range="-28 28"/>
            <joint axis="0 1 0" name="hip" type="hinge" range="-45 45"/>
            <geom fromto="0 0 0 0.3 0 0" name="leg" size="0.08" type="capsule"/>
            <body pos="0.3 0 0" euler="0 90 0">
              <joint axis="0 1 0" name="knee" type="hinge" range="-45 45"/>
              <geom fromto="0 0 0 0.6 0 0" name="knee" size="0.08" type="capsule"/>
              <geom name="foot" contype="1" pos="0.6 0 0" size="0.08" type="sphere" mass="0"/>
              <site name="foot" contype="1" pos="0.6 0 0" size="0.08" type="sphere" mass="0"/>
            </body>
          </body>
        </body>
      </replicate>
    </body>
  </worldbody>
  <actuator>
    <position name="roll" joint="roll"/>
    <position name="hip" joint="hip"/>
    <position name="knee" joint="knee"/>
  </actuator>
  <sensor>
    <accelerometer name="imu_accelerometer" site="imu"/>
    <gyro name="imu_gyro" site="imu"/>
    <touch name="foot" site="foot"/>
  </sensor>
</mujoco>
