<mujoco model="eye">
  <compiler angle="degree" coordinate="local" inertiafromgeom="true"/>
  <option timestep="0.01" iterations="4" />
  <custom>
    <!-- brax custom params -->
    <numeric data="0 0 0.55 1 0 0 0 0 0 0 0 0 0" name="init_qpos"/>
    <numeric data="1000" name="constraint_limit_stiffness"/>
    <numeric data="4000" name="constraint_stiffness"/>
    <numeric data="10" name="constraint_ang_damping"/>
    <numeric data="20" name="constraint_vel_damping"/>
    <numeric data="0.5" name="joint_scale_pos"/>
    <numeric data="0.2" name="joint_scale_ang"/>
    <numeric data="0" name="ang_damping"/>
    <numeric data="1" name="spring_mass_scale"/>
    <numeric data="1" name="spring_inertia_scale"/>
    <numeric data="15" name="solver_maxls"/>
  </custom>
  <default>
    <joint armature="1" damping="1" limited="true"/>
    <geom contype="0" conaffinity="0" condim="3" density="5" friction="1 0.5 0.5"
     rgba="0.4 0.33 0.26 1"/>
  </default>
  <asset>
    <texture builtin="gradient" height="100" rgb1="1 1 1" rgb2="0 0 0" type="skybox" width="100"/>
    <texture builtin="flat" height="1278" mark="cross" markrgb="1 1 1" name="texgeom" random="0.01" rgb1="0.8 0.6 0.4" rgb2="0.8 0.6 0.4" type="cube" width="127"/>
    <texture builtin="checker" height="100" name="texplane" rgb1="0 0 0" rgb2="0.8 0.8 0.8" type="2d" width="100"/>
    <material name="MatPlane" reflectance="0.5" shininess="1" specular="1" texrepeat="60 60" texture="texplane"/>
    <material name="geom" texture="texgeom" texuniform="true"/>
  </asset>
  <worldbody>
    <light cutoff="100" diffuse="1 1 1" dir="-0 0 -1.3" directional="true" exponent="1" pos="0 0 1.3" specular=".1 .1 .1"/>
    <geom conaffinity="1" condim="3" material="MatPlane" name="floor" pos="0 0 0" size="40 40 40" type="plane" rgba="0.5 0.5 0.5 1"/>
    <body name="torso" pos="0 0 0.75">
      <camera name="track" mode="trackcom" pos="0 -3 0.3" xyaxes="1 0 0 0 0 1"/>
      <geom name="torso_geom" pos="0 0 0" size="0.25" type="sphere"/>
      <joint armature="0" damping="0" limited="false" margin="0.01" name="root" pos="0 0 0" type="free"/>
      <replicate count="3" euler="0 0 120">
        <body name="leg" pos="0 0 0">
          <geom fromto="0 0 0 0.3 0 0" name="aux_geom" size="0.08" type="capsule"/>
          <body name="aux" pos="0.3 0 0">
            <joint axis="0 0 1" name="hip" pos="0 0 0" range="-30 30" type="hinge"/>
            <geom fromto="0 0 0 0.3 0 0" name="left_leg_geom" size="0.08" type="capsule"/>
            <body pos="0.3 0 0">
              <joint axis="0 1 0" name="ankle" pos="0 0 0" range="30 70" type="hinge"/>
              <geom fromto="0 0 0 0.6 0 0" name="left_ankle_geom" size="0.08" type="capsule"/>
              <geom name="left_foot_geom" contype="1" pos="0.6 0 0" size="0.08" type="sphere" mass="0"/>
            </body>
          </body>
        </body>
      </replicate>
    </body>
  </worldbody>
  <actuator>
    <motor ctrllimited="true" ctrlrange="-0.375 0.375" joint="hip" gear="150"/>
    <motor ctrllimited="true" ctrlrange="-0.375 0.375" joint="ankle" gear="150"/>
  </actuator>
</mujoco>
